"use strict";

function qwer(str = {}) {
  try {
    var _str$line;

    let b = str.line;
    console.log('走无报错的逻辑', b, typeof str);
  } catch (e) {
    console.log('看看是否报错', e);
  }
}

const a = undefined;
qwer(a);

return;

function noop() {}

// States:
//
// 0 - pending
// 1 - fulfilled with _value
// 2 - rejected with _value
// 3 - adopted the state of another promise, _value
//
// once the state is no longer pending (0) it is immutable

// All `_` prefixed properties will be reduced to `_{random number}`
// at build time to obfuscate them and discourage their use.
// We don't use symbols or Object.defineProperty to fully hide them
// because the performance isn't good enough.


// to avoid using try/catch inside critical functions, we
// extract them to here.
var LAST_ERROR = null;
var IS_ERROR = {};
function getThen(obj) {
  try {
    return obj.then;
  } catch (ex) {
    LAST_ERROR = ex;
    return IS_ERROR;
  }
}

function tryCallOne(fn, a) {
  try {
    return fn(a);
  } catch (ex) {
    LAST_ERROR = ex;
    return IS_ERROR;
  }
}
function tryCallTwo(fn, a, b) {
  try {
    fn(a, b);
  } catch (ex) {
    LAST_ERROR = ex;
    return IS_ERROR;
  }
}

module.exports = Promise;

function Promise(fn) {
  if (typeof this !== 'object') {
    throw new TypeError('Promises must be constructed via new');
  }
  if (typeof fn !== 'function') {
    throw new TypeError('Promise constructor\'s argument is not a function');
  }
  this._U = 0;
  this._V = 0;
  this._W = null;
  this._X = null;
  if (fn === noop) return;
  doResolve(fn, this);
}
Promise._Y = null;
Promise._Z = null;
Promise._0 = noop;

Promise.prototype.then = function(onFulfilled, onRejected) {
  if (this.constructor !== Promise) {
    return safeThen(this, onFulfilled, onRejected);
  }
  var res = new Promise(noop);
  handle(this, new Handler(onFulfilled, onRejected, res));
  return res;
};

function safeThen(self, onFulfilled, onRejected) {
  return new self.constructor(function (resolve, reject) {
    var res = new Promise(noop);
    res.then(resolve, reject);
    handle(self, new Handler(onFulfilled, onRejected, res));
  });
}
function handle(self, deferred) {
  while (self._V === 3) {
    self = self._W;
  }
  if (Promise._Y) {
    Promise._Y(self);
  }
  if (self._V === 0) {
    if (self._U === 0) {
      self._U = 1;
      self._X = deferred;
      return;
    }
    if (self._U === 1) {
      self._U = 2;
      self._X = [self._X, deferred];
      return;
    }
    self._X.push(deferred);
    return;
  }
  handleResolved(self, deferred);
}

function handleResolved(self, deferred) {
  setImmediate(function() {
    var cb = self._V === 1 ? deferred.onFulfilled : deferred.onRejected;
    if (cb === null) {
      if (self._V === 1) {
        resolve(deferred.promise, self._W);
      } else {
        reject(deferred.promise, self._W);
      }
      return;
    }
    var ret = tryCallOne(cb, self._W);
    if (ret === IS_ERROR) {
      reject(deferred.promise, LAST_ERROR);
    } else {
      resolve(deferred.promise, ret);
    }
  });
}
function resolve(self, newValue) {
  // Promise Resolution Procedure: https://github.com/promises-aplus/promises-spec#the-promise-resolution-procedure
  if (newValue === self) {
    return reject(
      self,
      new TypeError('A promise cannot be resolved with itself.')
    );
  }
  if (
    newValue &&
    (typeof newValue === 'object' || typeof newValue === 'function')
  ) {
    var then = getThen(newValue);
    if (then === IS_ERROR) {
      return reject(self, LAST_ERROR);
    }
    if (
      then === self.then &&
      newValue instanceof Promise
    ) {
      self._V = 3;
      self._W = newValue;
      finale(self);
      return;
    } else if (typeof then === 'function') {
      doResolve(then.bind(newValue), self);
      return;
    }
  }
  self._V = 1;
  self._W = newValue;
  finale(self);
}

function reject(self, newValue) {
  self._V = 2;
  self._W = newValue;
  if (Promise._Z) {
    Promise._Z(self, newValue);
  }
  finale(self);
}
function finale(self) {
  if (self._U === 1) {
    handle(self, self._X);
    self._X = null;
  }
  if (self._U === 2) {
    for (var i = 0; i < self._X.length; i++) {
      handle(self, self._X[i]);
    }
    self._X = null;
  }
}

function Handler(onFulfilled, onRejected, promise){
  this.onFulfilled = typeof onFulfilled === 'function' ? onFulfilled : null;
  this.onRejected = typeof onRejected === 'function' ? onRejected : null;
  this.promise = promise;
}

/**
 * Take a potentially misbehaving resolver function and make sure
 * onFulfilled and onRejected are only called once.
 *
 * Makes no guarantees about asynchrony.
 */
function doResolve(fn, promise) {
  var done = false;
  var res = tryCallTwo(fn, function (value) {
    if (done) return;
    done = true;
    resolve(promise, value);
  }, function (reason) {
    if (done) return;
    done = true;
    reject(promise, reason);
  });
  if (!done && res === IS_ERROR) {
    done = true;
    reject(promise, LAST_ERROR);
  }
}





'use strict';

// var Promise = require('./core');

var DEFAULT_WHITELIST = [
  ReferenceError,
  TypeError,
  RangeError
];

var enabled = false;
exports.disable = disable;
function disable() {
  enabled = false;
  Promise._Y = null;
  Promise._Z = null;
}

exports.enable = enable;
function enable(options) {
  options = options || {};
  if (enabled) disable();
  enabled = true;
  var id = 0;
  var displayId = 0;
  var rejections = {};
  Promise._Y = function (promise) {
    if (
      promise._V === 2 && // IS REJECTED
      rejections[promise._1]
    ) {
      if (rejections[promise._1].logged) {
        onHandled(promise._1);
      } else {
        clearTimeout(rejections[promise._1].timeout);
      }
      delete rejections[promise._1];
    }
  };
  Promise._Z = function (promise, err) {
    if (promise._U === 0) { // not yet handled
      promise._1 = id++;
      rejections[promise._1] = {
        displayId: null,
        error: err,
        timeout: setTimeout(
          onUnhandled.bind(null, promise._1),
          // For reference errors and type errors, this almost always
          // means the programmer made a mistake, so log them after just
          // 100ms
          // otherwise, wait 2 seconds to see if they get handled
          matchWhitelist(err, DEFAULT_WHITELIST)
            ? 100
            : 2000
        ),
        logged: false
      };
    }
  };
  function onUnhandled(id) {
    if (
      options.allRejections ||
      matchWhitelist(
        rejections[id].error,
        options.whitelist || DEFAULT_WHITELIST
      )
    ) {
      rejections[id].displayId = displayId++;
      if (options.onUnhandled) {
        rejections[id].logged = true;
        options.onUnhandled(
          rejections[id].displayId,
          rejections[id].error
        );
      } else {
        rejections[id].logged = true;
        logError(
          rejections[id].displayId,
          rejections[id].error
        );
      }
    }
  }
  function onHandled(id) {
    if (rejections[id].logged) {
      if (options.onHandled) {
        options.onHandled(rejections[id].displayId, rejections[id].error);
      } else if (!rejections[id].onUnhandled) {
        console.warn(
          'Promise Rejection Handled (id: ' + rejections[id].displayId + '):'
        );
        console.warn(
          '  This means you can ignore any previous messages of the form "Possible Unhandled Promise Rejection" with id ' +
          rejections[id].displayId + '.'
        );
      }
    }
  }
}

function logError(id, error) {
  console.warn('Possible Unhandled Promise Rejection (id: ' + id + '):');
  var errStr = (error && (error.stack || error)) + '';
  errStr.split('\n').forEach(function (line) {
    console.warn('  ' + line);
  });
}

function matchWhitelist(error, list) {
  return list.some(function (cls) {
    return error instanceof cls;
  });
}








enable({
  allRejections: true,
  onUnhandled: async (id, error = {}) => {
    let message;
    let stack;

    const stringValue = Object.prototype.toString.call(error);
    if (stringValue === '[object Error]') {
      message = Error.prototype.toString.call(error);
      stack = error.stack;
    } else {
      /* $FlowFixMe(>=0.54.0 site=react_native_oss) This comment suppresses
       * an error found when Flow v0.54 was deployed. To see the error delete
       * this comment and run Flow. */
      // message = require('pretty-format')(error);
    }
    console.log('自定义onUnhandled', error, typeof error);
    try {
      const line = error.line;
      const a = '';
      const b = a.qwer;
      console.log('看看有没有line报错', line, b);
    }
    catch (e) {
      console.log('下面的捕获是否有结果', e)
    }
    const warning = `
    Error:
      errorposition: ${error.line},${error.column},
      errormessage: ${error.message},
      errorurl: ${error.sourceURL},
    `;
    console.warn(warning);
  },
  onHandled: (id) => {
    const warning =
      `Promise Rejection Handled (id: ${id})\n` +
      'This means you can ignore any previous messages of the form ' +
      `"Possible Unhandled Promise Rejection (id: ${id}):"`;
    console.warn(warning);
  },
});

function test(obj) {
  return new Promise((resolve, reject) => {
    if (!obj || !obj.url || !obj.filePath) {
      reject('有问题');
    }
    return;
    test(obj).then((result) => {
      if (result && result.success) {
        resolve(result.data);
      } else {
        reject(result);
      }
    }).catch((err) => {
      reject(err);
    });
  })
}

test();

try {
  const a = undefined;
  const b = a.qwer;
  console.log('外面看看如何', b);
}
catch (e) {
  console.log('外面的捕获', e)
}
